Workbook

Sheet Receipt
A1: New Bedford FY2025 Taxpayer Receipt
A2: Where did your property tax go in FY2025? — interactive worksheet
A4: Your home’s assessed value | B4: 393323 | C4: ← type your single-family home’s assessed value here
A6: Your estimated annual residential property tax | B6: =B4*Data!B13/1000 -> 4448.4831 | C6: your assessed value × $11.31 per $1,000 — the FY2025 residential rate
A8: 1 · WHERE THE CITY’S MONEY CAME FROM
A9: For every $1 of residential property tax the city collected citywide, this is what it took in from each source.
A10: Revenue source | B10: FY2025 amount | C10: Per $1 residential
A11: State & federal grants and charges for service | B11: =Data!B24 -> 516934715 | C11: =B11/$B$12 -> 4.6600907
A12: Residential property tax | B12: =Data!B25 -> 110928037 | C12: =B12/$B$12 -> 1
A13: Commercial, industrial & personal property tax | B13: =Data!B26 -> 44151002 | C13: =B13/$B$12 -> 0.39801481
A14: Unrestricted state aid | B14: =Data!B27 -> 22033642 | C14: =B14/$B$12 -> 0.19863005
A15: Other local revenue | B15: =Data!B28 -> 20066710 | C15: =B15/$B$12 -> 0.18089845
A16: Motor vehicle & other excise | B16: =Data!B29 -> 9837910 | C16: =B16/$B$12 -> 0.088687317
A17: Net transfers from enterprise funds | B17: =Data!B30 -> 7983185 | C17: =B17/$B$12 -> 0.071967243
A18: Total city revenue | B18: =SUM(B11:B17) -> 731935201 | C18: =B18/$B$12 -> 6.5982886
A20: 2 · WHAT YOUR PROPERTY TAX FUNDED
A21: Your property tax, distributed across city functions by each function’s share of net local cost.
A22: City function | B22: Share of total | C22: Outside funding | D22: Your share
A23: Public safety | B23: =Data!B35/Data!$B$9 -> 0.27539073 | C23: =Data!C35 -> 0.299 | D23: =$B$6*B23 -> 1225.071
A24: Education — New Bedford Public Schools | B24: =Data!B36/Data!$B$9 -> 0.24432342 | C24: =Data!C36 -> 0.878 | D24: =$B$6*B24 -> 1086.8686
A25: General government | B25: =Data!B37/Data!$B$9 -> 0.20011953 | C25: =Data!C37 -> 0.191 | D25: =$B$6*B25 -> 890.22833
A26: Charter school tuition assessment | B26: =Data!B38/Data!$B$9 -> 0.1149089 | C26: =Data!C38 -> 0.205 | D26: =$B$6*B26 -> 511.17029
A27: Public works | B27: =Data!B39/Data!$B$9 -> 0.082117394 | C27: =Data!C39 -> 0.828 | D27: =$B$6*B27 -> 365.29784
A28: Interest on long-term debt | B28: =Data!B40/Data!$B$9 -> 0.037338051 | C28: =Data!C40 -> 0 | D28: =$B$6*B28 -> 166.09769
A29: Culture & recreation | B29: =Data!B41/Data!$B$9 -> 0.030764381 | C29: =Data!C41 -> 0.257 | D29: =$B$6*B29 -> 136.85483
A30: Health & human services | B30: =Data!B42/Data!$B$9 -> 0.015037605 | C30: =Data!C42 -> 0.705 | D30: =$B$6*B30 -> 66.894534
A31: Community & economic development | B31: — | C31: =Data!C43 -> 1 | D31: 0
A32: Your total property tax | D32: =SUM(D23:D31) -> 4448.4831
A34: Community & economic development is fully grant-funded (CDBG/HUD); it draws nothing from the property tax.
A35: Built into every function above: roughly $77M in employee pensions and health insurance — close to a tenth of city spending.

Sheet Data
A1: New Bedford FY2025 Taxpayer Receipt — Source Data
A2: Audited or reconciled FY2025 actuals. Hardcoded inputs in blue; formulas in black.
A4: KEY FIGURES
A5: Figure | B5: Value | C5: Unit | D5: Source
A6: Total governmental spending | B6: 729655324 | C6: $ | D6: New Bedford FY2025 ACFR, Statement of Activities, p. 24
A7: Total governmental revenue | B7: 731935201 | C7: $ | D7: New Bedford FY2025 ACFR, Statement of Activities, p. 24 — program and general revenue plus net transfers
A8: Net local cost — all 9 functions | B8: =B44 -> 211903120 | C8: $ | D8: Derived — sum of the functional ledger below
A9: Distribution base — 8 functions with positive net cost | B9: =B45 -> 212062221 | C9: $ | D9: Derived — functional ledger excluding Community & Economic Development
A10: Property tax revenue, net of abatements | B10: 155079039 | C10: $ | D10: New Bedford FY2025 ACFR, Statement of Activities, p. 24
A11: Residential assessed value | B11: 9818849124 | C11: $ | D11: New Bedford FY2025 ACFR, assessed-value-by-class table, p. 144
A12: Commercial, industrial & personal assessed value | B12: 1934217613 | C12: $ | D12: New Bedford FY2025 ACFR, assessed-value-by-class table, p. 144
A13: Residential tax rate | B13: 11.31 | C13: per $1,000 | D13: New Bedford FY2025 Tax Rate Recapitulation
A14: Commercial, industrial & personal tax rate | B14: 22.85 | C14: per $1,000 | D14: New Bedford FY2025 Tax Rate Recapitulation
A15: Residential share of the property tax levy | B15: =ROUND((B11*B13)/(B11*B13+B12*B14),4) -> 0.7153 | C15: share | D15: Derived — each class’s levy (assessed value × rate) as a share of the total levy
A16: Residential property tax | B16: =ROUND(B10*B15,0) -> 110928037 | C16: $ | D16: Derived — property tax revenue × residential share
A17: Commercial, industrial & personal property tax | B17: =B10-B16 -> 44151002 | C17: $ | D17: Derived — property tax revenue less residential property tax
A18: Citywide motor vehicle & other excise | B18: 9837910 | C18: $ | D18: New Bedford FY2025 ACFR, Statement of Activities, p. 24 — includes business-registered vehicles and boat excise
A19: Average single-family assessed value | B19: 393323 | C19: $ | D19: Massachusetts Department of Revenue, presented at New Bedford’s FY2025 tax classification hearing
A20: Average single-family tax bill | B20: =B19*B13/1000 -> 4448.4831 | C20: $ | D20: Derived — average value × residential rate
A22: REVENUE SOURCES — WHERE THE CITY’S MONEY CAME FROM
A23: Revenue source | B23: FY2025 amount | D23: Source
A24: State & federal grants and charges for service | B24: 516934715 | D24: ACFR p. 24 — operating and capital grants plus charges for services
A25: Residential property tax | B25: =B16 -> 110928037 | D25: Derived — see Key figures, row 16
A26: Commercial, industrial & personal property tax | B26: =B17 -> 44151002 | D26: Derived — see Key figures, row 17
A27: Unrestricted state aid | B27: 22033642 | D27: ACFR p. 24 — net of the charter reimbursement reattributed to charter tuition
A28: Other local revenue | B28: 20066710 | D28: ACFR p. 24 — penalties, interest, investment income, and other local receipts
A29: Motor vehicle & other excise | B29: =B18 -> 9837910 | D29: Derived — see Key figures, row 18
A30: Net transfers from enterprise funds | B30: 7983185 | D30: ACFR p. 24 — transfers in less transfers out
A31: Total | B31: =SUM(B24:B30) -> 731935201 | D31: Equals total governmental revenue (row 7)
A33: GOVERNMENTAL FUNCTIONS — NET LOCAL COST
A34: City function | B34: Net local cost (FY2025) | C34: Outside-funded share | D34: Source
A35: Public safety | B35: 58399969 | C35: 0.299 | D35: ACFR p. 24 — net of program revenue and restricted aid
A36: Education — New Bedford Public Schools | B36: 51811767 | C36: 0.878 | D36: ACFR p. 24
A37: General government | B37: 42437791 | C37: 0.191 | D37: ACFR p. 24
A38: Charter school tuition assessment | B38: 24367836 | C38: 0.205 | D38: DESE FY2025 charter reconciliation — gross $30,659,589 less $6,291,753 state reimbursement
A39: Public works | B39: 17413997 | C39: 0.828 | D39: ACFR p. 24
A40: Interest on long-term debt | B40: 7917990 | C40: 0 | D40: ACFR p. 24
A41: Culture & recreation | B41: 6523963 | C41: 0.257 | D41: ACFR p. 24
A42: Health & human services | B42: 3188908 | C42: 0.705 | D42: ACFR p. 24
A43: Community & economic development | B43: -159101 | C43: 1 | D43: ACFR p. 24 — net local cost is slightly negative; fully grant-funded, shown as $0 on the receipt
...

Sheet Notes
A1: New Bedford FY2025 Taxpayer Receipt — Workbook Notes
A3: What this is
A4: An auditable companion to the New Bedford FY2025 Taxpayer Receipt. The Receipt sheet reproduces the
A5: receipt with live formulas; the Data sheet holds every underlying figure with its source. Change the
A6: assessed value in the highlighted cell on the Receipt sheet and every figure recalculates.
A8: Method, in brief
A9: The receipt follows a net-local-cost approach modeled on the National Priorities Project federal receipt.
A10: Each function’s net local cost is its gross expense less program revenue and restricted aid — the part
A11: carried by local revenue. A household’s residential property tax is then distributed across functions in
A12: proportion to each function’s share of net local cost. Charter tuition is separated from education, with
A13: the state charter reimbursement attributed to it as an offset. The full methodology is in methodology.md,
A14: in the same repository.
... A30: Not a publication of the City of New Bedford, and not reviewed or endorsed by the City.
